Workbook

Sheet README
A1: Program Plan & Cost Book: Two 5-Axis Machining Centers + Robotic Loading Cell
A2: Mock customer program built as a project management portfolio piece. Customer and all figures are fictional and illustrative.
A4: Scenario | B4: Fictional customer Lakeshore Drivetrain Co. orders two 5-axis horizontal machining centers, two hydraulic fixture sets and a robotic loading cell to machine an aluminum transmission housing.
A5: How to use | B5: Blue text = inputs you can change. Black = formulas. Green = links from another tab. Yellow fill = key assumptions.
A6: Schedule | B6: Change durations, predecessors-driven start dates recalculate with WORKDAY. Gantt bars redraw from the dates.
A7: Quote Build-up | B7: Cost lines x markup = quoted price. Feeds the Cost Book budget.
A8: Cost Book | B8: Budget vs committed vs actual vs estimate-to-complete. EAC and variance calculate automatically.
A9: Change Log | B9: Customer change requests priced as supplementary quotes; approved ones roll into the revised contract on the Dashboard.
A10: Risk Register | B10: Probability x impact scoring with mitigation owners.
A11: Runoff Checklist | B11: Acceptance criteria checked at our plant and at the customer site.
A12: Dashboard | B12: One-page status for the customer program review: contract, margin, schedule health.

Sheet Dashboard
A1: Program Review Dashboard
A2: Lakeshore Drivetrain Co. (fictional), two 5-axis machining centers + robotic loading cell
A4: COMMERCIAL | D4: SCHEDULE
A5: Original contract value ($) | B5: ='Quote Build-up'!H18 -> 2375922.3 | D5: Status date | E5: =Schedule!E3 -> 46493
A6: Approved change orders ($) | B6: ='Change Log'!F8 -> 24000 | D6: Planned project finish | E6: =MAX(Schedule!G6:G47) -> 46577
A7: Revised contract value ($) | B7: =B5+B6 -> 2399922.3 | D7: Overall % complete (duration-weighted) | E7: =IFERROR(SUMPRODUCT((Schedule!I6:I47<>"")*Schedule!D6:D47*Schedule!H6:H47)/SUMPRODUCT((Schedule!I6:I47<>"")*Schedule!D6:D47),0) -> 0.70310078
A8: Pending change orders ($) | B8: ='Change Log'!F9 -> 54300 | D8: Tasks late | E8: =COUNTIF(Schedule!I6:I47,"LATE") -> 1
A9: Budget cost incl. approved COs ($) | B9: ='Cost Book'!C17+'Change Log'!E8 -> 1969715 | D9: Tasks in progress | E9: =COUNTIF(Schedule!I6:I47,"In progress") -> 2
A10: Estimate at completion ($) | B10: ='Cost Book'!G17+'Change Log'!E8 -> 1958966 | D10: Approved CO days (absorbed by float) | E10: ='Change Log'!G8 -> 5
A11: Forecast margin ($) | B11: =B7-B10 -> 440956.3 | D11: High risks open | E11: =COUNTIF('Risk Register'!F5:F9,"High") -> 2
A12: Quoted margin % | B12: ='Quote Build-up'!H19 -> 0.17875471 | D12: Runoff items passed (our plant) | E12: ='Runoff Checklist'!E12 -> 0 of 7
A13: Forecast margin % | B13: =IFERROR(B11/B7,0) -> 0.18373774 | D13: Overall status | E13: =IF(OR(E8>0,B14<-0.02),"AMBER: action needed","GREEN") -> AMBER: action needed
A14: Margin change vs quote (pts) | B14: =B13-B12 -> 0.0049830309
A16: Talking points for program review
A17: - Robot cell delivery is late; integration resequenced, expedite fee covered from contingency.
A18: - Machine line is forecast over budget on the second spindle; contingency released to offset.
A19: - CO-02 and CO-03 priced and sent as supplementary quotes; need customer decision before guarding work starts.

Sheet Schedule
A1: Project Schedule (Customer Time Schedule)
A2: Start dates are driven by predecessors (finish-to-start, working days). Status is judged against the status date.
A3: Project start | B3: 46391 | D3: Status date | E3: 46493 | G3: Holidays | H3: 46538 | I3: 46573
K4: Gantt (week starting): dark blue = task, light = summary, orange = late, red = milestone
A5: WBS | B5: Task | C5: Owner | D5: Duration (days) | E5: Predecessors | F5: Start | G5: Finish | H5: % Complete | I5: Status | K5: =$B$3-WEEKDAY($B$3,3)+0 -> 46391 | L5: =$B$3-WEEKDAY($B$3,3)+7 -> 46398 | M5: =$B$3-WEEKDAY($B$3,3)+14 -> 46405 | N5: =$B$3-WEEKDAY($B$3,3)+21 -> 46412 | O5: =$B$3-WEEKDAY($B$3,3)+28 -> 46419 | P5: =$B$3-WEEKDAY($B$3,3)+35 -> 46426 | Q5: =$B$3-WEEKDAY($B$3,3)+42 -> 46433 | R5: =$B$3-WEEKDAY($B$3,3)+49 -> 46440 | S5: =$B$3-WEEKDAY($B$3,3)+56 -> 46447 | T5: =$B$3-WEEKDAY($B$3,3)+63 -> 46454 | U5: =$B$3-WEEKDAY($B$3,3)+70 -> 46461 | V5: =$B$3-WEEKDAY($B$3,3)+77 -> 46468 | W5: =$B$3-WEEKDAY($B$3,3)+84 -> 46475 | X5: =$B$3-WEEKDAY($B$3,3)+91 -> 46482 | Y5: =$B$3-WEEKDAY($B$3,3)+98 -> 46489 | Z5: =$B$3-WEEKDAY($B$3,3)+105 -> 46496 | AA5: =$B$3-WEEKDAY($B$3,3)+112 -> 46503 | AB5: =$B$3-WEEKDAY($B$3,3)+119 -> 46510 | AC5: =$B$3-WEEKDAY($B$3,3)+126 -> 46517 | AD5: =$B$3-WEEKDAY($B$3,3)+133 -> 46524 | AE5: =$B$3-WEEKDAY($B$3,3)+140 -> 46531 | AF5: =$B$3-WEEKDAY($B$3,3)+147 -> 46538 | AG5: =$B$3-WEEKDAY($B$3,3)+154 -> 46545 | AH5: =$B$3-WEEKDAY($B$3,3)+161 -> 46552 | AI5: =$B$3-WEEKDAY($B$3,3)+168 -> 46559 | AJ5: =$B$3-WEEKDAY($B$3,3)+175 -> 46566 | AK5: =$B$3-WEEKDAY($B$3,3)+182 -> 46573 | AL5: =$B$3-WEEKDAY($B$3,3)+189 -> 46580
A6: 1 | B6: RFQ & Quotation | D6: =NETWORKDAYS(F6,G6,$H$3:$I$3) -> 21 | F6: =MIN(F7:F14) -> 46391 | G6: =MAX(G7:G14) -> 46419 | H6: =IFERROR(SUMPRODUCT(D7:D14,H7:H14)/SUM(D7:D14),0) -> 1
A7: 1.1 | B7: Receive RFQ and SOW, log in quote tracker | C7: Project Manager | D7: 1 | F7: =$B$3 -> 46391 | G7: =IF(D7=0,F7,WORKDAY(F7,D7-1,$H$3:$I$3)) -> 46391 | H7: 1 | I7: =IF(H7>=1,"Done",IF(G7<$E$3,"LATE",IF(F7<=$E$3,"In progress","Not started"))) -> Done
A8: 1.2 | B8: Technical evaluation of scope (part, cycle time, tolerances) | C8: Applications Engineer | D8: 3 | E8: 1.1 | F8: =WORKDAY(MAX(G7),1,$H$3:$I$3) -> 46392 | G8: =IF(D8=0,F8,WORKDAY(F8,D8-1,$H$3:$I$3)) -> 46394 | H8: 1 | I8: =IF(H8>=1,"Done",IF(G8<$E$3,"LATE",IF(F8<=$E$3,"In progress","Not started"))) -> Done
A9: 1.3 | B9: Send clarification questions to customer | C9: Project Manager | D9: 2 | E9: 1.2 | F9: =WORKDAY(MAX(G8),1,$H$3:$I$3) -> 46395 | G9: =IF(D9=0,F9,WORKDAY(F9,D9-1,$H$3:$I$3)) -> 46398 | H9: 1 | I9: =IF(H9>=1,"Done",IF(G9<$E$3,"LATE",IF(F9<=$E$3,"In progress","Not started"))) -> Done
A10: 1.4 | B10: Build cost estimate in Quote Build-up | C10: Project Manager | D10: 4 | E10: 1.3 | F10: =WORKDAY(MAX(G9),1,$H$3:$I$3) -> 46399 | G10: =IF(D10=0,F10,WORKDAY(F10,D10-1,$H$3:$I$3)) -> 46402 | H10: 1 | I10: =IF(H10>=1,"Done",IF(G10<$E$3,"LATE",IF(F10<=$E$3,"In progress","Not started"))) -> Done
A11: 1.5 | B11: Internal quote review and approval | C11: Sales Manager | D11: 1 | E11: 1.4 | F11: =WORKDAY(MAX(G10),1,$H$3:$I$3) -> 46405 | G11: =IF(D11=0,F11,WORKDAY(F11,D11-1,$H$3:$I$3)) -> 46405 | H11: 1 | I11: =IF(H11>=1,"Done",IF(G11<$E$3,"LATE",IF(F11<=$E$3,"In progress","Not started"))) -> Done
A12: 1.6 | B12: Quote submitted to customer | C12: Project Manager | D12: 0 | E12: 1.5 | F12: =MAX(G11) -> 46405 | G12: =IF(D12=0,F12,WORKDAY(F12,D12-1,$H$3:$I$3)) -> 46405 | H12: 1 | I12: =IF(H12>=1,"Done",IF(G12<$E$3,"LATE",IF(F12<=$E$3,"In progress","Not started"))) -> Done
A13: 1.7 | B13: Customer negotiation and PO | C13: Sales Manager | D13: 10 | E13: 1.6 | F13: =WORKDAY(MAX(G12),1,$H$3:$I$3) -> 46406 | G13: =IF(D13=0,F13,WORKDAY(F13,D13-1,$H$3:$I$3)) -> 46419 | H13: 1 | I13: =IF(H13>=1,"Done",IF(G13<$E$3,"LATE",IF(F13<=$E$3,"In progress","Not started"))) -> Done
A14: 1.8 | B14: Customer PO received | C14: Project Manager | D14: 0 | E14: 1.7 | F14: =MAX(G13) -> 46419 | G14: =IF(D14=0,F14,WORKDAY(F14,D14-1,$H$3:$I$3)) -> 46419 | H14: 1 | I14: =IF(H14>=1,"Done",IF(G14<$E$3,"LATE",IF(F14<=$E$3,"In progress","Not started"))) -> Done
A15: 2 | B15: Order Release | D15: =NETWORKDAYS(F15,G15,$H$3:$I$3) -> 5 | F15: =MIN(F16:F19) -> 46420 | G15: =MAX(G16:G19) -> 46426 | H15: =IFERROR(SUMPRODUCT(D16:D19,H16:H19)/SUM(D16:D19),0) -> 1
A16: 2.1 | B16: Scope-of-supply check: PO vs quote | C16: Project Manager | D16: 2 | E16: 1.8 | F16: =WORKDAY(MAX(G14),1,$H$3:$I$3) -> 46420 | G16: =IF(D16=0,F16,WORKDAY(F16,D16-1,$H$3:$I$3)) -> 46421 | H16: 1 | I16: =IF(H16>=1,"Done",IF(G16<$E$3,"LATE",IF(F16<=$E$3,"In progress","Not started"))) -> Done
A17: 2.2 | B17: Internal job order release | C17: Project Manager | D17: 0 | E17: 2.1 | F17: =MAX(G16) -> 46421 | G17: =IF(D17=0,F17,WORKDAY(F17,D17-1,$H$3:$I$3)) -> 46421 | H17: 1 | I17: =IF(H17>=1,"Done",IF(G17<$E$3,"LATE",IF(F17<=$E$3,"In progress","Not started"))) -> Done
A18: 2.3 | B18: Issue customer time schedule | C18: Project Manager | D18: 2 | E18: 2.2 | F18: =WORKDAY(MAX(G17),1,$H$3:$I$3) -> 46422 | G18: =IF(D18=0,F18,WORKDAY(F18,D18-1,$H$3:$I$3)) -> 46423 | H18: 1 | I18: =IF(H18>=1,"Done",IF(G18<$E$3,"LATE",IF(F18<=$E$3,"In progress","Not started"))) -> Done
A19: 2.4 | B19: Kickoff meeting with customer | C19: Project Manager | D19: 1 | E19: 2.3 | F19: =WORKDAY(MAX(G18),1,$H$3:$I$3) -> 46426 | G19: =IF(D19=0,F19,WORKDAY(F19,D19-1,$H$3:$I$3)) -> 46426 | H19: 1 | I19: =IF(H19>=1,"Done",IF(G19<$E$3,"LATE",IF(F19<=$E$3,"In progress","Not started"))) -> Done
A20: 3 | B20: Engineering | D20: =NETWORKDAYS(F20,G20,$H$3:$I$3) -> 27 | F20: =MIN(F21:F24) -> 46422 | G20: =MAX(G21:G24) -> 46458 | H20: =IFERROR(SUMPRODUCT(D21:D24,H21:H24)/SUM(D21:D24),0) -> 1
A21: 3.1 | B21: Fixture design (hydraulic, 2 sets) | C21: Mechanical Design | D21: 15 | E21: 2.2 | F21: =WORKDAY(MAX(G17),1,$H$3:$I$3) -> 46422 | G21: =IF(D21=0,F21,WORKDAY(F21,D21-1,$H$3:$I$3)) -> 46442 | H21: 1 | I21: =IF(H21>=1,"Done",IF(G21<$E$3,"LATE",IF(F21<=$E$3,"In progress","Not started"))) -> Done
A22: 3.2 | B22: Robot cell layout and guarding design | C22: Automation Engineer | D22: 15 | E22: 2.2 | F22: =WORKDAY(MAX(G17),1,$H$3:$I$3) -> 46422 | G22: =IF(D22=0,F22,WORKDAY(F22,D22-1,$H$3:$I$3)) -> 46442 | H22: 1 | I22: =IF(H22>=1,"Done",IF(G22<$E$3,"LATE",IF(F22<=$E$3,"In progress","Not started"))) -> Done
A23: 3.3 | B23: CNC process and program development | C23: Applications Engineer | D23: 12 | E23: 3.1 | F23: =WORKDAY(MAX(G21),1,$H$3:$I$3) -> 46443 | G23: =IF(D23=0,F23,WORKDAY(F23,D23-1,$H$3:$I$3)) -> 46458 | H23: 1 | I23: =IF(H23>=1,"Done",IF(G23<$E$3,"LATE",IF(F23<=$E$3,"In progress","Not started"))) -> Done
A24: 3.4 | B24: Customer design review approved | C24: Project Manager | D24: 0 | E24: 3.1, 3.2 | F24: =MAX(G21,G22) -> 46442 | G24: =IF(D24=0,F24,WORKDAY(F24,D24-1,$H$3:$I$3)) -> 46442 | H24: 1 | I24: =IF(H24>=1,"Done",IF(G24<$E$3,"LATE",IF(F24<=$E$3,"In progress","Not started"))) -> Done
A25: 4 | B25: Procurement | D25: =NETWORKDAYS(F25,G25,$H$3:$I$3) -> 45 | F25: =MIN(F26:F28) -> 46422 | G25: =MAX(G26:G28) -> 46484 | H25: =IFERROR(SUMPRODUCT(D26:D28,H26:H28)/SUM(D26:D28),0) -> 0.91666667
A26: 4.1 | B26: Long-lead items: spindles and CNC controls | C26: Purchasing | D26: 40 | E26: 2.2 | F26: =WORKDAY(MAX(G17),1,$H$3:$I$3) -> 46422 | G26: =IF(D26=0,F26,WORKDAY(F26,D26-1,$H$3:$I$3)) -> 46477 | H26: 1 | I26: =IF(H26>=1,"Done",IF(G26<$E$3,"LATE",IF(F26<=$E$3,"In progress","Not started"))) -> Done
A27: 4.2 | B27: Robot and safety guarding | C27: Purchasing | D27: 30 | E27: 3.4 | F27: =WORKDAY(MAX(G24),1,$H$3:$I$3) -> 46443 | G27: =IF(D27=0,F27,WORKDAY(F27,D27-1,$H$3:$I$3)) -> 46484 | H27: 0.75 | I27: =IF(H27>=1,"Done",IF(G27<$E$3,"LATE",IF(F27<=$E$3,"In progress","Not started"))) -> LATE
A28: 4.3 | B28: Fixture components | C28: Purchasing | D28: 20 | E28: 3.4 | F28: =WORKDAY(MAX(G24),1,$H$3:$I$3) -> 46443 | G28: =IF(D28=0,F28,WORKDAY(F28,D28-1,$H$3:$I$3)) -> 46470 | H28: 1 | I28: =IF(H28>=1,"Done",IF(G28<$E$3,"LATE",IF(F28<=$E$3,"In progress","Not started"))) -> Done
A29: 5 | B29: Build & Assembly | D29: =NETWORKDAYS(F29,G29,$H$3:$I$3) -> 37 | F29: =MIN(F30:F33) -> 46471 | G29: =MAX(G30:G33) -> 46521 | H29: =IFERROR(SUMPRODUCT(D30:D33,H30:H33)/SUM(D30:D33),0) -> 0.4983871
A30: 5.1 | B30: Machine 1 assembly | C30: Assembly | D30: 20 | E30: 4.1 | F30: =WORKDAY(MAX(G26),1,$H$3:$I$3) -> 46478 | G30: =IF(D30=0,F30,WORKDAY(F30,D30-1,$H$3:$I$3)) -> 46505 | H30: 0.55 | I30: =IF(H30>=1,"Done",IF(G30<$E$3,"LATE",IF(F30<=$E$3,"In progress","Not started"))) -> In progress
A31: 5.2 | B31: Machine 2 assembly | C31: Assembly | D31: 22 | E31: 4.1 | F31: =WORKDAY(MAX(G26),1,$H$3:$I$3) -> 46478 | G31: =IF(D31=0,F31,WORKDAY(F31,D31-1,$H$3:$I$3)) -> 46507 | H31: 0.45 | I31: =IF(H31>=1,"Done",IF(G31<$E$3,"LATE",IF(F31<=$E$3,"In progress","Not started"))) -> In progress
A32: 5.3 | B32: Fixture build and CMM inspection | C32: Quality | D32: 10 | E32: 4.3 | F32: =WORKDAY(MAX(G28),1,$H$3:$I$3) -> 46471 | G32: =IF(D32=0,F32,WORKDAY(F32,D32-1,$H$3:$I$3)) -> 46484 | H32: 1 | I32: =IF(H32>=1,"Done",IF(G32<$E$3,"LATE",IF(F32<=$E$3,"In progress","Not started"))) -> Done
A33: 5.4 | B33: Cell integration and controls I/O check | C33: Controls Engineer | D33: 10 | E33: 5.1, 5.2, 5.3, 4.2 | F33: =WORKDAY(MAX(G30,G31,G32,G27),1,$H$3:$I$3) -> 46510 | G33: =IF(D33=0,F33,WORKDAY(F33,D33-1,$H$3:$I$3)) -> 46521 | H33: 0 | I33: =IF(H33>=1,"Done",IF(G33<$E$3,"LATE",IF(F33<=$E$3,"In progress","Not started"))) -> Not started
A34: 6 | B34: Runoff & Acceptance | D34: =NETWORKDAYS(F34,G34,$H$3:$I$3) -> 8 | F34: =MIN(F35:F37) -> 46524 | G34: =MAX(G35:G37) -> 46533 | H34: =IFERROR(SUMPRODUCT(D35:D37,H35:H37)/SUM(D35:D37),0) -> 0
A35: 6.1 | B35: Internal quality check against runoff checklist | C35: Quality | D35: 3 | E35: 5.4 | F35: =WORKDAY(MAX(G33),1,$H$3:$I$3) -> 46524 | G35: =IF(D35=0,F35,WORKDAY(F35,D35-1,$H$3:$I$3)) -> 46526 | H35: 0 | I35: =IF(H35>=1,"Done",IF(G35<$E$3,"LATE",IF(F35<=$E$3,"In progress","Not started"))) -> Not started
A36: 6.2 | B36: Pre-acceptance runoff at our plant (Cpk study) | C36: Applications Engineer | D36: 5 | E36: 6.1, 3.3 | F36: =WORKDAY(MAX(G35,G23),1,$H$3:$I$3) -> 46527 | G36: =IF(D36=0,F36,WORKDAY(F36,D36-1,$H$3:$I$3)) -> 46533 | H36: 0 | I36: =IF(H36>=1,"Done",IF(G36<$E$3,"LATE",IF(F36<=$E$3,"In progress","Not started"))) -> Not started
A37: 6.3 | B37: Customer buy-off signed | C37: Project Manager | D37: 0 | E37: 6.2 | F37: =MAX(G36) -> 46533 | G37: =IF(D37=0,F37,WORKDAY(F37,D37-1,$H$3:$I$3)) -> 46533 | H37: 0 | I37: =IF(H37>=1,"Done",IF(G37<$E$3,"LATE",IF(F37<=$E$3,"In progress","Not started"))) -> Not started
A38: 7 | B38: Delivery & Installation | D38: =NETWORKDAYS(F38,G38,$H$3:$I$3) -> 25 | F38: =MIN(F39:F43) -> 46534 | G38: =MAX(G39:G43) -> 46569 | H38: =IFERROR(SUMPRODUCT(D39:D43,H39:H43)/SUM(D39:D43),0) -> 0
A39: 7.1 | B39: Teardown, crate and ship | C39: Logistics | D39: 7 | E39: 6.3 | F39: =WORKDAY(MAX(G37),1,$H$3:$I$3) -> 46534 | G39: =IF(D39=0,F39,WORKDAY(F39,D39-1,$H$3:$I$3)) -> 46545 | H39: 0 | I39: =IF(H39>=1,"Done",IF(G39<$E$3,"LATE",IF(F39<=$E$3,"In progress","Not started"))) -> Not started
A40: 7.2 | B40: Installation and leveling at customer site | C40: Service | D40: 10 | E40: 7.1 | F40: =WORKDAY(MAX(G39),1,$H$3:$I$3) -> 46546 | G40: =IF(D40=0,F40,WORKDAY(F40,D40-1,$H$3:$I$3)) -> 46559 | H40: 0 | I40: =IF(H40>=1,"Done",IF(G40<$E$3,"LATE",IF(F40<=$E$3,"In progress","Not started"))) -> Not started
...

Sheet Quote Build-up
A1: Quote Build-up (RFQ response)
A2: Cost estimate per scope line, marked up to the quoted sell price. Quantities, unit costs and markups are inputs.
A3: Default markup | C3: 0.22 | D3: Assumption: markup on cost (22% markup = about 18% margin on sell price); illustrative.
A5: Line | B5: Scope item | C5: Unit | D5: Qty | E5: Unit cost ($) | F5: Cost ($) | G5: Markup | H5: Sell price ($)
A6: Machine | B6: 5-axis horizontal machining center (base machine) | C6: ea | D6: 2 | E6: 620000 | F6: =D6*E6 -> 1240000 | G6: =$C$3 -> 0.22 | H6: =F6*(1+G6) -> 1512800
A7: Fixture | B7: Hydraulic fixture set, single nest | C7: set | D7: 2 | E7: 47500 | F7: =D7*E7 -> 95000 | G7: =$C$3 -> 0.22 | H7: =F7*(1+G7) -> 115900
A8: Automation | B8: Robotic loading cell incl. safety guarding | C8: lot | D8: 1 | E8: 180000 | F8: =D8*E8 -> 180000 | G8: =$C$3 -> 0.22 | H8: =F8*(1+G8) -> 219600
A9: Controls | B9: Controls and software integration | C9: lot | D9: 1 | E9: 45000 | F9: =D9*E9 -> 45000 | G9: =$C$3 -> 0.22 | H9: =F9*(1+G9) -> 54900
A10: Eng labor | B10: Engineering hours (mech, controls, apps) | C10: hr | D10: 900 | E10: 95 | F10: =D10*E10 -> 85500 | G10: =$C$3 -> 0.22 | H10: =F10*(1+G10) -> 104310
A11: Assy labor | B11: Assembly hours | C11: hr | D11: 1400 | E11: 70 | F11: =D11*E11 -> 98000 | G11: =$C$3 -> 0.22 | H11: =F11*(1+G11) -> 119560
A12: Runoff | B12: Runoff and applications support | C12: hr | D12: 240 | E12: 95 | F12: =D12*E12 -> 22800 | G12: =$C$3 -> 0.22 | H12: =F12*(1+G12) -> 27816
A13: Freight | B13: Freight, crating and rigging | C13: lot | D13: 1 | E13: 38000 | F13: =D13*E13 -> 38000 | G13: 0.1 | H13: =F13*(1+G13) -> 41800
A14: Install | B14: Installation and travel | C14: lot | D14: 1 | E14: 42000 | F14: =D14*E14 -> 42000 | G14: =$C$3 -> 0.22 | H14: =F14*(1+G14) -> 51240
A15: Training | B15: Operator and maintenance training | C15: lot | D15: 1 | E15: 12000 | F15: =D15*E15 -> 12000 | G15: =$C$3 -> 0.22 | H15: =F15*(1+G15) -> 14640
B16: Warranty reserve (% of cost) | D16: 0.02 | F16: =SUM(F6:F15)*D16 -> 37166 | G16: =$C$3 -> 0.22 | H16: =F16*(1+G16) -> 45342.52
B17: Contingency (% of cost) | D17: 0.03 | F17: =SUM(F6:F15)*D17 -> 55749 | G17: =$C$3 -> 0.22 | H17: =F17*(1+G17) -> 68013.78
B18: TOTAL | F18: =SUM(F6:F17) -> 1951215 | H18: =SUM(H6:H17) -> 2375922.3
B19: Quoted margin | H19: =IFERROR((H18-F18)/H18,0) -> 0.17875471

Sheet Cost Book
A1: Project Cost Book
A2: Budget comes from the quote. Committed = POs placed. Actual = invoiced/booked to date. ETC = estimate to complete. EAC = Actual + ETC.
A4: Line | B4: Cost item | C4: Budget ($) | D4: Committed ($) | E4: Actual to date ($) | F4: Est. to complete ($) | G4: EAC ($) | H4: Variance ($) | I4: Variance % | J4: Note
A5: Machine | B5: ='Quote Build-up'!B6 -> 5-axis horizontal machining center (base machine) | C5: ='Quote Build-up'!F6 -> 1240000 | D5: 1250000 | E5: 610000 | F5: 640000 | G5: =E5+F5 -> 1250000 | H5: =C5-G5 -> -10000 | I5: =IFERROR(H5/C5,0) -> -0.0080645161 | J5: Machine 2 spindle quote came in higher
A6: Fixture | B6: ='Quote Build-up'!B7 -> Hydraulic fixture set, single nest | C6: ='Quote Build-up'!F7 -> 95000 | D6: 95000 | E6: 88000 | F6: 7000 | G6: =E6+F6 -> 95000 | H6: =C6-G6 -> 0 | I6: =IFERROR(H6/C6,0) -> 0
A7: Automation | B7: ='Quote Build-up'!B8 -> Robotic loading cell incl. safety guarding | C7: ='Quote Build-up'!F8 -> 180000 | D7: 186500 | E7: 140000 | F7: 46500 | G7: =E7+F7 -> 186500 | H7: =C7-G7 -> -6500 | I7: =IFERROR(H7/C7,0) -> -0.036111111 | J7: Robot delivery 1 week late; expedite fee
A8: Controls | B8: ='Quote Build-up'!B9 -> Controls and software integration | C8: ='Quote Build-up'!F9 -> 45000 | D8: 30000 | E8: 12000 | F8: 33000 | G8: =E8+F8 -> 45000 | H8: =C8-G8 -> 0 | I8: =IFERROR(H8/C8,0) -> 0
A9: Eng labor | B9: ='Quote Build-up'!B10 -> Engineering hours (mech, controls, apps) | C9: ='Quote Build-up'!F10 -> 85500 | D9: 0 | E9: 71000 | F9: 16000 | G9: =E9+F9 -> 87000 | H9: =C9-G9 -> -1500 | I9: =IFERROR(H9/C9,0) -> -0.01754386 | J9: Hours tracked from timesheets
A10: Assy labor | B10: ='Quote Build-up'!B11 -> Assembly hours | C10: ='Quote Build-up'!F11 -> 98000 | D10: 0 | E10: 52000 | F10: 48000 | G10: =E10+F10 -> 100000 | H10: =C10-G10 -> -2000 | I10: =IFERROR(H10/C10,0) -> -0.020408163
A11: Runoff | B11: ='Quote Build-up'!B12 -> Runoff and applications support | C11: ='Quote Build-up'!F12 -> 22800 | D11: 0 | E11: 0 | F11: 22800 | G11: =E11+F11 -> 22800 | H11: =C11-G11 -> 0 | I11: =IFERROR(H11/C11,0) -> 0
A12: Freight | B12: ='Quote Build-up'!B13 -> Freight, crating and rigging | C12: ='Quote Build-up'!F13 -> 38000 | D12: 0 | E12: 0 | F12: 38000 | G12: =E12+F12 -> 38000 | H12: =C12-G12 -> 0 | I12: =IFERROR(H12/C12,0) -> 0
A13: Install | B13: ='Quote Build-up'!B14 -> Installation and travel | C13: ='Quote Build-up'!F14 -> 42000 | D13: 0 | E13: 0 | F13: 42000 | G13: =E13+F13 -> 42000 | H13: =C13-G13 -> 0 | I13: =IFERROR(H13/C13,0) -> 0
A14: Training | B14: ='Quote Build-up'!B15 -> Operator and maintenance training | C14: ='Quote Build-up'!F15 -> 12000 | D14: 0 | E14: 0 | F14: 12000 | G14: =E14+F14 -> 12000 | H14: =C14-G14 -> 0 | I14: =IFERROR(H14/C14,0) -> 0
A15: Warranty | B15: ='Quote Build-up'!B16 -> Warranty reserve (% of cost) | C15: ='Quote Build-up'!F16 -> 37166 | D15: 0 | E15: 0 | F15: =C15 -> 37166 | G15: =E15+F15 -> 37166 | H15: =C15-G15 -> 0 | I15: =IFERROR(H15/C15,0) -> 0 | J15: Held until warranty period ends
A16: Contingency | B16: ='Quote Build-up'!B17 -> Contingency (% of cost) | C16: ='Quote Build-up'!F17 -> 55749 | D16: 0 | E16: 0 | F16: 25000 | G16: =E16+F16 -> 25000 | H16: =C16-G16 -> 30749 | I16: =IFERROR(H16/C16,0) -> 0.55156146 | J16: Partly released to absorb machine and robot overruns; $25k held for install risk
B17: TOTAL | C17: =SUM(C5:C16) -> 1951215 | D17: =SUM(D5:D16) -> 1561500 | E17: =SUM(E5:E16) -> 973000 | F17: =SUM(F5:F16) -> 967466 | G17: =SUM(G5:G16) -> 1940466 | H17: =SUM(H5:H16) -> 10749 | I17: =IFERROR(H17/C17,0) -> 0.0055088752
B19: Variance = Budget - EAC. Negative (red) means the line is forecast over budget.

Sheet Change Log
A1: Change Log and Supplementary Quotes
A2: Every customer change is priced as a supplementary quote. Only Approved changes count toward the revised contract.
A4: CO # | B4: Description | C4: Requested by | D4: Date | E4: Added cost ($) | F4: Supplementary quote ($) | G4: Schedule impact (days) | H4: Status
A5: CO-01 | B5: Add part variant B: second nest on each fixture, new CNC program (absorbed by fixture float) | C5: Customer | D5: 46448 | E5: 18500 | F5: 24000 | G5: 5 | H5: Approved
A6: CO-02 | B6: Spare spindle cartridge for customer stock | C6: Customer | D6: 46486 | E6: 32000 | F6: 41600 | G6: 0 | H6: Pending
A7: CO-03 | B7: Upgrade guarding to customer corporate safety standard | C7: Customer | D7: 46491 | E7: 9800 | F7: 12700 | G7: 3 | H7: Pending
B8: Approved total | E8: =SUMIF(H5:H7,"Approved",E5:E7) -> 18500 | F8: =SUMIF(H5:H7,"Approved",F5:F7) -> 24000 | G8: =SUMIF(H5:H7,"Approved",G5:G7) -> 5
B9: Pending total | E9: =SUMIF(H5:H7,"Pending",E5:E7) -> 41800 | F9: =SUMIF(H5:H7,"Pending",F5:F7) -> 54300

Sheet Risk Register
A1: Risk Register
A2: Probability and impact on a 1-5 scale. Score = P x I. 15+ is high, 8-14 medium.
A4: ID | B4: Risk | C4: Probability (1-5) | D4: Impact (1-5) | E4: Score | F4: Rating | G4: Mitigation | H4: Owner
A5: R1 | B5: Long-lead spindle or control delivery slips | C5: 3 | D5: 5 | E5: =C5*D5 -> 15 | F5: =IF(E5>=15,"High",IF(E5>=8,"Medium","Low")) -> High | G5: Order at job release; weekly supplier check-in; track in schedule | H5: Purchasing
A6: R2 | B6: Part fails Cpk 1.33 at runoff | C6: 2 | D6: 5 | E6: =C6*D6 -> 10 | F6: =IF(E6>=15,"High",IF(E6>=8,"Medium","Low")) -> Medium | G6: Early capability trial on machine 1; fixture CMM check before runoff | H6: Applications Engineer
A7: R3 | B7: Customer scope creep without paperwork | C7: 4 | D7: 3 | E7: =C7*D7 -> 12 | F7: =IF(E7>=15,"High",IF(E7>=8,"Medium","Low")) -> Medium | G7: Every change through Change Log and supplementary quote before work starts | H7: Project Manager
A8: R4 | B8: Robot cell delivery late (now happening) | C8: 5 | D8: 3 | E8: =C8*D8 -> 15 | F8: =IF(E8>=15,"High",IF(E8>=8,"Medium","Low")) -> High | G8: Expedite fee budgeted from contingency; resequence integration | H8: Project Manager
A9: R5 | B9: Site not ready for install (foundation, power, air) | C9: 2 | D9: 4 | E9: =C9*D9 -> 8 | F9: =IF(E9>=15,"High",IF(E9>=8,"Medium","Low")) -> Medium | G9: Send site-prep checklist 8 weeks before ship; confirm at program review | H9: Service

Sheet Runoff Checklist
A1: Runoff Checklist
A2: Acceptance criteria agreed with the customer at order. Pre-acceptance at our plant, final at customer site.
A4: # | B4: Check | C4: Requirement | D4: Method | E4: Our plant | F4: Customer site
A5: 1 | B5: Cycle time per part | C5: <= 4.5 min | D5: Timed 30-part run | E5: Open | F5: Open
A6: 2 | B6: Process capability, critical bores | C6: Cpk >= 1.33 | D6: CMM, 30 consecutive parts | E6: Open | F6: Open
A7: 3 | B7: Position tolerance, bolt pattern | C7: Per drawing, datums A|B|C | D7: CMM report | E7: Open | F7: Open
A8: 4 | B8: Unattended run | C8: 4 hours, no stops | D8: Robot cell continuous run | E8: Open | F8: Open
A9: 5 | B9: Safety guarding and interlocks | C9: Customer safety standard | D9: Interlock test sheet | E9: Open | F9: Open
A10: 6 | B10: Documentation package | C10: Manuals, electrical prints, spares list | D10: Checklist sign-off | E10: Open | F10: Open
A11: 7 | B11: Operator training | C11: 2 shifts trained | D11: Attendance sign-off | E11: Open | F11: Open
B12: Items passed at our plant | E12: =COUNTIF(E5:E11,"Pass")&" of "&COUNTA(E5:E11) -> 0 of 7
